Workbook
Name Tax_rate: 'DCF model'!$C$26
Name UPDATE: 'Data Sheet (2)'!$E$1
Name UPDATE: #REF!

Sheet Data Sheet (2)
A1: COMPANY NAME | B1: HDFC BANK LTD | E1: =IF(B2<>B3, "A NEW VERSION OF THE WORKSHEET IS AVAILABLE", "")
A2: LATEST VERSION | B2: 2.1 | E2: PLEASE DO NOT MAKE ANY CHANGES TO THIS SHEET
A3: CURRENT VERSION | B3: 2.1
A5: META
A6: Number of shares | B6: =IF(B9>0, B9/B8, 0) -> 1541.8597
A7: Face Value | B7: 1
A8: Current Price | B8: 721.2
A9: Market Capitalization | B9: 1111989.2
A15: PROFIT & LOSS
A16: Report Date | B16: 42825 | C16: 43190 | D16: 43555 | E16: 43921 | F16: 44286 | G16: 44651 | H16: 45016 | I16: 45382 | J16: 45747 | K16: 46112
A17: Sales | B17: 73271.35 | C17: 85287.84 | D17: 105160.74 | E17: 122189.29 | F17: 128552.4 | G17: 135936.41 | H17: 170754.05 | I17: 283649.02 | J17: 336367.43 | K17: 348615.15
A18: Raw Material Cost
A19: Change in Inventory
A20: Power and Fuel
A21: Other Mfr. Exp | B21: 1271.8 | C21: 1314.97 | D21: 1283.53 | E21: 1293.44 | F21: 1649.11 | G21: 1772.27 | H21: 2176.5 | I21: 3255.75 | J21: 3943.56 | K21: 4691.2
A22: Employee Cost | B22: 8508.22 | C22: 9197.15 | D22: 10454.75 | E22: 12924.1 | F22: 13682.35 | G22: 15904.81 | H22: 20031.36 | I22: 31050.07 | J22: 34167.89 | K22: 37645.25
A23: Selling and admin | B23: 3328.39 | C23: 3658.43 | D23: 3900.17 | E23: 4192.15 | F23: 4780.54 | G23: 5406.79 | H23: 6580 | I23: 87580.05 | J23: 105188.45 | K23: 103553.02
A24: Other Expenses | B24: 10747.28 | C24: 15361.71 | D24: 19217.82 | E24: 27049.52 | F24: 32344.53 | G24: 33473.09 | H24: 34254.44 | I24: 52309.67 | J24: 43674.55 | K24: 57745.76
A25: Other Income | B25: 12905.08 | C25: 16056.6 | D25: 18947.05 | E25: 24878.97 | F25: 27332.88 | G25: 31758.99 | H25: 33912.05 | I25: 124345.75 | J25: 134548.5 | K25: 146847.66
A26: Depreciation | B26: 886.19 | C26: 966.78 | D26: 1220.67 | E26: 1276.77 | F26: 1385.01 | G26: 1680.73 | H26: 2345.47 | I26: 3092.08 | J26: 3805.23 | K26: 4194.9
A27: Interest | B27: 38041.58 | C27: 42381.48 | D27: 53712.69 | E27: 62137.42 | F27: 59247.59 | G27: 58584.33 | H27: 77779.94 | I27: 154138.55 | J27: 183894.2 | K27: 185491.23
A28: Profit before tax | B28: 23392.97 | C28: 28463.92 | D28: 34318.16 | E28: 38194.86 | F28: 42796.15 | G28: 50873.38 | H28: 61498.39 | I28: 76568.6 | J28: 96242.05 | K28: 102141.45
A29: Tax | B29: 8078.12 | C29: 9903.08 | D29: 11872.55 | E29: 10898.59 | F29: 10939.38 | G29: 12722.48 | H29: 15349.69 | I29: 11122.1 | J29: 22801.88 | K29: 22921.99
A30: Net profit | B30: 15280.48 | C30: 18510.02 | D30: 22332.43 | E30: 27253.95 | F30: 31833.21 | G30: 38052.75 | H30: 45997.11 | I30: 64062.04 | J30: 70792.25 | K30: 76025.97
A31: Dividend Amount | B31: 2818.8 | C31: 3373.63 | D31: 4084.95 | E31: 1370.82 | F31: 3583.32 | G31: 8595.52 | H31: 10601.43 | I31: 14813.96 | J31: 16834.84 | K31: 23859.77
A40: Quarters
A41: Report Date | B41: 45382 | C41: 45473 | D41: 45565 | E41: 45657 | F41: 45747 | G41: 45838 | H41: 45930 | I41: 46022 | J41: 46112 | K41: 46203
A42: Sales | B42: 79433.61 | C42: 81546.2 | D42: 83001.72 | E42: 85040.17 | F42: 86779.34 | G42: 87371.87 | H42: 86993.84 | I42: 87066.94 | J42: 87182.5 | K42: 90575.33
A43: Expenses | B43: 62938.45 | C43: 49689.62 | D43: 52074.11 | E43: 41306.79 | F43: 47709.16 | G43: 64496.63 | H43: 45160.88 | I43: 54144.75 | J43: 44027.87 | K43: 58291.57
A44: Other Income | B44: 44957.74 | C44: 35450.29 | D44: 38455.02 | E44: 27153.77 | F44: 33489.42 | G44: 45683.1 | H44: 31566.79 | I44: 39860.33 | J44: 29737.44 | K44: 42535.03
A45: Depreciation
A46: Interest | B46: 43691.51 | C46: 44579.5 | D46: 45414.21 | E46: 46914.28 | F46: 46986.21 | G46: 47708.51 | H46: 46740.86 | I46: 45821.42 | J46: 45220.44 | K46: 47625.63
A47: Profit before tax | B47: 17761.39 | C47: 22727.37 | D47: 23968.42 | E47: 23972.87 | F47: 25573.39 | G47: 20849.83 | H47: 26658.89 | I47: 26961.1 | J47: 27671.63 | K47: 27193.16
A48: Tax | B48: -251.48 | C48: 5539.32 | D48: 5340.98 | E48: 5632.76 | F48: 6288.82 | G48: 3759.4 | H48: 6295.12 | I48: 6270.06 | J48: 6597.41 | K48: 6810.47
A49: Net profit | B49: 17622.38 | C49: 16474.85 | D49: 17825.91 | E49: 17656.61 | F49: 18834.88 | G49: 16257.91 | H49: 19610.67 | I49: 19806.63 | J49: 20350.76 | K49: 19244.71
A50: Operating Profit | B50: 16495.16 | C50: 31856.58 | D50: 30927.61 | E50: 43733.38 | F50: 39070.18 | G50: 22875.24 | H50: 41832.96 | I50: 32922.19 | J50: 43154.63 | K50: 32283.76
A55: BALANCE SHEET
A56: Report Date | B56: 42825 | C56: 43190 | D56: 43555 | E56: 43921 | F56: 44286 | G56: 44651 | H56: 45016 | I56: 45382 | J56: 45747 | K56: 46112
A57: Equity Share Capital | B57: 512.51 | C57: 519.02 | D57: 544.66 | E57: 548.33 | F57: 551.28 | G57: 554.55 | H57: 557.97 | I57: 759.69 | J57: 765.22 | K57: 1539.34
A58: Reserves | B58: 91281.44 | C58: 109080.11 | D58: 153128 | E58: 175810.38 | F58: 209258.9 | G58: 246771.62 | H58: 288879.53 | I58: 455635.56 | J58: 521024.17 | K58: 584520.13
...

Sheet DCF model
A1: DISCOUNTED CASH FLOW MODEL
A3: Company Overview
A4: HDFC Bank Limited (HDFC Bank)
A5: Is one of India’s leading private sector banks, providing a wide range of banking and financial services to individuals, businesses, and large corporates across India.
A7: Key Products & Services:
A8: Savings Accounts | Current Accounts | Credit Cards | Personal Loans | Home Loans | Auto Loans | Fixed Deposits |
A9: Business Loans | Insurance & Mutual Fund Distribution | Wealth Management | Digital Banking
A11: Market Position:
A12: One of India's leading private sector banks | Extensive branch and ATM network |
A13: Strong presence across urban, semi-urban and rural India | Wide retail and corporate customer base | Strong digital banking capabilities
A15: Key Assumptions and methodology
A16: Parameter | C16: Value | D16: Rationable
A17: valuation date
A18: Projection period
A19: Revenue growth % | C19: 0.12 | D19: declining PAT growth assumption
A20: Annual Growth tapering | C20: 0.01
A22: Terminal Growth Rate | C22: 0.06 | D22: Conservative long term considering India's GDP
A24: Risk - Free Rate (Rf) | C24: 0.0721 | D24: 10 year Indian government Bond Yield
A25: Equity Risk Premium (ERP) | C25: =14.209%-C24 -> 0.06999 | D25: Expected return over risk free rate of equity investors
A26: Tax Rate | C26: 0.25 | D26: Effective tax rate base on historical data
A30: Financial performance ( ₹ Crores)
A31: INCOME STATEMENT
A32: Particulars | B32: FY22A | C32: FY23A | D32: FY24A | E32: FY25A | F32: FY26A | H32: CAGR
A33: Sales | B33: 135936.41 | C33: 170754.05 | D33: 283649.02 | E33: 336367.43 | F33: 348615.15
A34: % Growth | C34: =C33/B33-1 -> 0.25613182 | D34: =D33/C33-1 -> 0.66115545 | E34: =E33/D33-1 -> 0.1858579 | F34: =F33/E33-1 -> 0.03641173 | H34: =_xlfn.RRI(4,B33,F33) -> 0.26547222
A36: Cost of Goods Sold | B36: =SUM('Data Sheet (2)'!G18,-'Data Sheet (2)'!G19,'Data Sheet (2)'!G20:G21) -> 1772.27 | C36: =SUM('Data Sheet (2)'!H18,-'Data Sheet (2)'!H19,'Data Sheet (2)'!H20:H21) -> 2176.5 | D36: =SUM('Data Sheet (2)'!I18,-'Data Sheet (2)'!I19,'Data Sheet (2)'!I20:I21) -> 3255.75 | E36: =SUM('Data Sheet (2)'!J18,-'Data Sheet (2)'!J19,'Data Sheet (2)'!J20:J21) -> 3943.56 | F36: =SUM('Data Sheet (2)'!K18,-'Data Sheet (2)'!K19,'Data Sheet (2)'!K20:K21) -> 4691.2
A37: % of Revenue | B37: =B36/B33 -> 0.013037493 | C37: =C36/C33 -> 0.012746403 | D37: =D36/D33 -> 0.011478094 | E37: =E36/E33 -> 0.011723965 | F37: =F36/F33 -> 0.013456673
A38: Gross Profit | B38: =B33-B36 -> 134164.14 | C38: =C33-C36 -> 168577.55 | D38: =D33-D36 -> 280393.27 | E38: =E33-E36 -> 332423.87 | F38: =F33-F36 -> 343923.95
A39: Gross Margin % | B39: =B38/B33 -> 0.98696251 | C39: =C38/C33 -> 0.9872536 | D39: =D38/D33 -> 0.98852191 | E39: =E38/E33 -> 0.98827603 | F39: =F38/F33 -> 0.98654333
A40: Operating Expenses | B40: =SUM('Data Sheet (2)'!G22:G24) -> 54784.69 | C40: =SUM('Data Sheet (2)'!H22:H24) -> 60865.8 | D40: =SUM('Data Sheet (2)'!I22:I24) -> 170939.79 | E40: =SUM('Data Sheet (2)'!J22:J24) -> 183030.89 | F40: =SUM('Data Sheet (2)'!K22:K24) -> 198944.03
A41: % of Revenue | B41: =B40/B33 -> 0.40301704 | C41: =C40/C33 -> 0.35645304 | D41: =D40/D33 -> 0.60264545 | E41: =E40/E33 -> 0.54413975 | F41: =F40/F33 -> 0.57066949
A43: EBITDA | B43: =B38-B40 -> 79379.45 | C43: =C38-C40 -> 107711.75 | D43: =D38-D40 -> 109453.48 | E43: =E38-E40 -> 149392.98 | F43: =F38-F40 -> 144979.92
A44: EBITDA Margin % | B44: =B43/B33 -> 0.58394546 | C44: =C43/C33 -> 0.63080056 | D44: =D43/D33 -> 0.38587646 | E44: =E43/E33 -> 0.44413628 | F44: =F43/F33 -> 0.41587384
A46: Depreciation & Amortisation | B46: ='Data Sheet (2)'!G26 -> 1680.73 | C46: ='Data Sheet (2)'!H26 -> 2345.47 | D46: ='Data Sheet (2)'!I26 -> 3092.08 | E46: ='Data Sheet (2)'!J26 -> 3805.23 | F46: ='Data Sheet (2)'!K26 -> 4194.9
A47: % of sales | B47: =B46/B33 -> 0.01236409 | C47: =C46/C33 -> 0.013735955 | D47: =D46/D33 -> 0.010901078 | E47: =E46/E33 -> 0.011312718 | F47: =F46/F33 -> 0.01203304
A48: EBIT | B48: =B43-B46 -> 77698.72 | C48: =C43-C46 -> 105366.28 | D48: =D43-D46 -> 106361.4 | E48: =E43-E46 -> 145587.75 | F48: =F43-F46 -> 140785.02
A49: EBIT Margin % | B49: =B48/B33 -> 0.57158137 | C49: =C48/C33 -> 0.6170646 | D49: =D48/D33 -> 0.37497538 | E49: =E48/E33 -> 0.43282356 | F49: =F48/F33 -> 0.4038408
A51: Other Income | B51: ='Data Sheet (2)'!G25 -> 31758.99 | C51: ='Data Sheet (2)'!H25 -> 33912.05 | D51: ='Data Sheet (2)'!I25 -> 124345.75 | E51: ='Data Sheet (2)'!J25 -> 134548.5 | F51: ='Data Sheet (2)'!K25 -> 146847.66
A52: Interest | B52: ='Data Sheet (2)'!G27 -> 58584.33 | C52: ='Data Sheet (2)'!H27 -> 77779.94 | D52: ='Data Sheet (2)'!I27 -> 154138.55 | E52: ='Data Sheet (2)'!J27 -> 183894.2 | F52: ='Data Sheet (2)'!K27 -> 185491.23
A53: % of debt | B53: =B52/'Data Sheet (2)'!G59 -> 0.032820913 | C53: =C52/'Data Sheet (2)'!H59 -> 0.036359156 | D53: =D52/'Data Sheet (2)'!I59 -> 0.049602064 | E53: =E52/'Data Sheet (2)'!J59 -> 0.054967566 | F53: =F52/'Data Sheet (2)'!K59 -> 0.050294211
...

Sheet comparable companies Analysis
A1: COMPANIES DATA
A2: S.No. | B2: Company | C2: CMP Rs. | D2: P/E | E2: Mar Cap Rs.Cr. | F2: Sales Rs.Cr. | G2: EPS 12M Rs. | H2: Debt Rs.Cr. | I2: EV / EBITDA | J2: EV Rs.Cr. | K2: IV Rs. | L2: beta | M2: Cash Equivalents | N2: NP(Cr)
A3: 1 | B3: HDFC Bank | C3: 721.2 | D3: 14.07 | E3: 1111989.2 | F3: 351818.61 | G3: 51.35 | H3: 3733201.9 | I3: 15.97 | J3: 4694611.4 | K3: 747.71 | L3: 0.92 | M3: 150579.79 | N3: 82511.72
A4: 2 | B4: ICICI Bank | C4: 1310.6 | D4: 16.77 | E4: 940846.48 | F4: 198379.35 | G4: 78.36 | H4: 2096680.5 | I4: 17.65 | J4: 2963517.9 | K4: 1020.15 | L4: 0.99 | M4: 74009.08 | N4: 59756.14
A5: 3 | B5: Kotak Mah. Bank | C5: 418.35 | D5: 20.78 | E5: 416169.61 | F5: 70887.47 | G5: 20.41 | H5: 662333.86 | I5: 18.06 | J5: 1027221.7 | K5: 305.85 | L5: 0.89 | M5: 51281.74 | N5: 20296.17
A6: 4 | B6: Axis Bank | C6: 1217.1 | D6: 13.64 | E6: 378967.18 | F6: 135731.89 | G6: 89.39 | H6: 1656431.1 | I6: 17.92 | J6: 1976741.4 | K6: 1112.66 | L6: 1.03 | M6: 58656.85 | N6: 27938.79
A7: 5 | B7: IDBI Bank | C7: 86.57 | D7: 9.99 | E7: 93083.55 | F7: 29542.24 | G7: 8.67 | H7: 374879.89 | I7: 15.75 | J7: 434732.97 | K7: 88.01 | L7: 0.9 | M7: 33230.47 | N7: 9343.31
A9: INDUSTRY DATA
A10: Company | B10: Equity value | C10: Total Debt | D10: Debt/Equity | E10: Debt/Capital | F10: Tax rate % | G10: Levered beta | H10: Unlevered beta
A11: ICICI Bank | B11: =E4 -> 940846.48 | C11: =H4 -> 2096680.5 | D11: =C11/B11 -> 2.2285043 | E11: =C11/(B11+C11) -> 0.69025905 | F11: =Tax_rate -> 0.25 | G11: =L4 -> 0.99 | H11: =G11/(1+D11)*(1-Tax_rate) -> 0.22998266
A12: Kotak Mah. Bank | B12: =E5 -> 416169.61 | C12: =H5 -> 662333.86 | D12: =C12/B12 -> 1.5914998 | E12: =C12/(B12+C12) -> 0.61412307 | F12: =Tax_rate -> 0.25 | G12: =L5 -> 0.89 | H12: =G12/(1+D12)*(1-Tax_rate) -> 0.25757285
A13: Axis Bank | B13: =E6 -> 378967.18 | C13: =H6 -> 1656431.1 | D13: =C13/B13 -> 4.370909 | E13: =C13/(B13+C13) -> 0.81381178 | F13: =Tax_rate -> 0.25 | G13: =L6 -> 1.03 | H13: =G13/(1+D13)*(1-Tax_rate) -> 0.1438304
A14: IDBI Bank | B14: =E7 -> 93083.55 | C14: =H7 -> 374879.89 | D14: =C14/B14 -> 4.0273484 | E14: =C14/(B14+C14) -> 0.80108799 | F14: =Tax_rate -> 0.25 | G14: =L7 -> 0.9 | H14: =G14/(1+D14)*(1-Tax_rate) -> 0.13426561
A16: Average | D16: =AVERAGE(D11:D14) -> 3.0545654 | E16: =AVERAGE(E11:E14) -> 0.72982047 | F16: =AVERAGE(F11:F14) -> 0.25 | G16: =AVERAGE(G11:G14) -> 0.9525 | H16: =AVERAGE(H11:H14) -> 0.19141288
A17: Median | D17: =MEDIAN(D11:D14) -> 3.1279264 | E17: =MEDIAN(E11:E14) -> 0.74567352 | F17: =MEDIAN(F11:J14) -> 0.25 | G17: =MEDIAN(G11:K14) -> 0.57378643 | H17: =MEDIAN(H11:H14) -> 0.18690653
A21: COMPAREABLE COMPANIES ANALYSIS
B22: Market Data | I22: Financial Data | K22: Valuation
A23: Company name | B23: price(per share) | C23: Shares | D23: Market cap(₹ Cr) | E23: Debt | F23: Cash & Equivalents | G23: EV (₹cr) | H23: Sales (₹cr) | I23: EBITDA(₹ Cr) | J23: Earnings (₹ Cr) | K23: EV/Sales (X) | L23: EV / EBITDA(X) | M23: P/E(X)
A24: ICICI Bank | B24: =C4 -> 1310.6 | C24: =D24/B24 -> 717.87462 | D24: =E4 -> 940846.48 | E24: =H4 -> 2096680.5 | F24: =M4 -> 74009.08 | G24: =D24+E24-F24 -> 2963517.9 | H24: =F4 -> 198379.35 | I24: =J4/I4 -> 167904.69 | J24: =N4 -> 59756.14 | K24: =G24/H24 -> 14.938641 | L24: =G24/I24 -> 17.65 | M24: =D24/J24 -> 15.744767
A25: Kotak Mah. Bank | B25: =C5 -> 418.35 | C25: =D25/B25 -> 994.78812 | D25: =E5 -> 416169.61 | E25: =H5 -> 662333.86 | F25: =M5 -> 51281.74 | G25: =D25+E25-F25 -> 1027221.7 | H25: =F5 -> 70887.47 | I25: =J5/I5 -> 56878.28 | J25: =N5 -> 20296.17 | K25: =G25/H25 -> 14.490879 | L25: =G25/I25 -> 18.06 | M25: =D25/J25 -> 20.504835
A26: Axis Bank | B26: =C6 -> 1217.1 | C26: =D26/B26 -> 311.36898 | D26: =E6 -> 378967.18 | E26: =H6 -> 1656431.1 | F26: =M6 -> 58656.85 | G26: =D26+E26-F26 -> 1976741.4 | H26: =F6 -> 135731.89 | I26: =J6/I6 -> 110309.23 | J26: =N6 -> 27938.79 | K26: =G26/H26 -> 14.563574 | L26: =G26/I26 -> 17.92 | M26: =D26/J26 -> 13.564194
A27: IDBI Bank | B27: =C7 -> 86.57 | C27: =D27/B27 -> 1075.2403 | D27: =E7 -> 93083.55 | E27: =H7 -> 374879.89 | F27: =M7 -> 33230.47 | G27: =D27+E27-F27 -> 434732.97 | H27: =F7 -> 29542.24 | I27: =J7/I7 -> 27602.093 | J27: =N7 -> 9343.31 | K27: =G27/H27 -> 14.71564 | L27: =G27/I27 -> 15.75 | M27: =D27/J27 -> 9.9625882
A29: Average | K29: =AVERAGE(K24:K27) -> 14.677183 | L29: =AVERAGE(L24:L27) -> 17.345 | M29: =AVERAGE(M24:M27) -> 14.944096
A30: Median | K30: =MEDIAN(K24:K27) -> 14.639607 | L30: =MEDIAN(L24:L27) -> 17.785 | M30: =MEDIAN(M24:M27) -> 14.654481
A32: HDFC BANK | B32: =C3 -> 721.2 | C32: =D32/B32 -> 1541.8597 | D32: =E3 -> 1111989.2 | E32: =H3 -> 3733201.9 | F32: =M3 -> 150579.79 | G32: =D32+E32-F32 -> 4694611.4 | H32: =F3 -> 351818.61 | I32: =J3/I3 -> 293964.39 | J32: =N3 -> 82511.72 | K32: =G32/H32 -> 13.34384 | L32: =G32/I32 -> 15.97 | M32: =D32/J32 -> 13.476743
A35: Metric | B35: Comps | C35: EV | D35: Net Debt | E35: Equity Value | F35: Shares | G35: Shares Price
A36: EV/Sales | B36: {=TRANSPOSE(K30:M30)} -> 14.639607 | C36: =H32*B36 -> 5150486.1 | D36: =$E$32-F32 -> 3582622.1 | E36: =C36-D36 -> 1567864 | F36: =$C$32 -> 1541.8597 | G36: =E36/F36 -> 1016.8655
A37: EV/EBITDA | B37: 17.785 | C37: =I32*B37 -> 5228156.8 | D37: =$E$32-F32 -> 3582622.1 | E37: =C37-D37 -> 1645534.6 | F37: =$C$32 -> 1541.8597 | G37: =E37/F37 -> 1067.2402
A38: P/E Ratio | B38: 14.654481 | C38: =E38+D38 -> 4791788.5 | D38: =$E$32-F32 -> 3582622.1 | E38: =B38*J32 -> 1209166.4 | F38: =$C$32 -> 1541.8597 | G38: =E38/F38 -> 784.22594
